[2024-05-02T17:44:53.378+0530] {local_task_job_runner.py:120} INFO - ::group::Pre task execution logs
[2024-05-02T17:44:53.385+0530] {taskinstance.py:2073} INFO - Dependencies all met for dep_context=non-requeueable deps ti=<TaskInstance: bharat2_dag.square_task manual__2024-05-02T12:09:45.697550+00:00 [queued]>
[2024-05-02T17:44:53.388+0530] {taskinstance.py:2073} INFO - Dependencies all met for dep_context=requeueable deps ti=<TaskInstance: bharat2_dag.square_task manual__2024-05-02T12:09:45.697550+00:00 [queued]>
[2024-05-02T17:44:53.388+0530] {taskinstance.py:2303} INFO - Starting attempt 2 of 2
[2024-05-02T17:44:53.394+0530] {taskinstance.py:2327} INFO - Executing <Task(PythonOperator): square_task> on 2024-05-02 12:09:45.697550+00:00
[2024-05-02T17:44:53.397+0530] {standard_task_runner.py:63} INFO - Started process 47284 to run task
[2024-05-02T17:44:53.398+0530] {standard_task_runner.py:90} INFO - Running: ['airflow', 'tasks', 'run', 'bharat2_dag', 'square_task', 'manual__2024-05-02T12:09:45.697550+00:00', '--job-id', '157', '--raw', '--subdir', 'DAGS_FOLDER/bharat3_dag.py', '--cfg-path', '/tmp/tmpoxvu5136']
[2024-05-02T17:44:53.399+0530] {standard_task_runner.py:91} INFO - Job 157: Subtask square_task
[2024-05-02T17:44:53.416+0530] {task_command.py:426} INFO - Running <TaskInstance: bharat2_dag.square_task manual__2024-05-02T12:09:45.697550+00:00 [running]> on host ninebit5lm
[2024-05-02T17:44:53.444+0530] {taskinstance.py:2644} INFO - Exporting env vars: AIRFLOW_CTX_DAG_OWNER='airflow' AIRFLOW_CTX_DAG_ID='bharat2_dag' AIRFLOW_CTX_TASK_ID='square_task' AIRFLOW_CTX_EXECUTION_DATE='2024-05-02T12:09:45.697550+00:00' AIRFLOW_CTX_TRY_NUMBER='2' AIRFLOW_CTX_DAG_RUN_ID='manual__2024-05-02T12:09:45.697550+00:00'
[2024-05-02T17:44:53.444+0530] {taskinstance.py:430} INFO - ::endgroup::
[2024-05-02T17:44:53.445+0530] {taskinstance.py:441} INFO - ::group::Post task execution logs
[2024-05-02T17:44:53.445+0530] {taskinstance.py:2890} ERROR - Task failed with exception
Traceback (most recent call last):
  File "/usr/local/lib/python3.10/dist-packages/airflow/models/taskinstance.py", line 465, in _execute_task
    result = _execute_callable(context=context, **execute_callable_kwargs)
  File "/usr/local/lib/python3.10/dist-packages/airflow/models/taskinstance.py", line 432, in _execute_callable
    return execute_callable(context=context, **execute_callable_kwargs)
  File "/usr/local/lib/python3.10/dist-packages/airflow/models/baseoperator.py", line 400, in wrapper
    return func(self, *args, **kwargs)
  File "/usr/local/lib/python3.10/dist-packages/airflow/operators/python.py", line 235, in execute
    return_value = self.execute_callable()
  File "/usr/local/lib/python3.10/dist-packages/airflow/operators/python.py", line 252, in execute_callable
    return self.python_callable(*self.op_args, **self.op_kwargs)
  File "/home/bharat/airflow/dags/bharat3_dag.py", line 14, in square_number
    return num ** 2
TypeError: unsupported operand type(s) for ** or pow(): 'str' and 'int'
[2024-05-02T17:44:53.446+0530] {taskinstance.py:1205} INFO - Marking task as FAILED. dag_id=bharat2_dag, task_id=square_task, execution_date=20240502T120945, start_date=20240502T121453, end_date=20240502T121453
[2024-05-02T17:44:53.451+0530] {standard_task_runner.py:110} ERROR - Failed to execute job 157 for task square_task (unsupported operand type(s) for ** or pow(): 'str' and 'int'; 47284)
[2024-05-02T17:44:53.490+0530] {local_task_job_runner.py:240} INFO - Task exited with return code 1
[2024-05-02T17:44:53.500+0530] {taskinstance.py:3482} INFO - 0 downstream tasks scheduled from follow-on schedule check
[2024-05-02T17:44:53.500+0530] {local_task_job_runner.py:222} INFO - ::endgroup::
