[2024-05-03T11:24:02.181+0530] {local_task_job_runner.py:120} INFO - ::group::Pre task execution logs
[2024-05-03T11:24:02.187+0530] {taskinstance.py:2073} INFO - Dependencies all met for dep_context=non-requeueable deps ti=<TaskInstance: bharat_dag.task_1 scheduled__2024-05-03T05:52:00+00:00 [queued]>
[2024-05-03T11:24:02.189+0530] {taskinstance.py:2073} INFO - Dependencies all met for dep_context=requeueable deps ti=<TaskInstance: bharat_dag.task_1 scheduled__2024-05-03T05:52:00+00:00 [queued]>
[2024-05-03T11:24:02.190+0530] {taskinstance.py:2303} INFO - Starting attempt 1 of 2
[2024-05-03T11:24:02.198+0530] {taskinstance.py:2327} INFO - Executing <Task(PythonOperator): task_1> on 2024-05-03 05:52:00+00:00
[2024-05-03T11:24:02.200+0530] {standard_task_runner.py:63} INFO - Started process 9796 to run task
[2024-05-03T11:24:02.201+0530] {standard_task_runner.py:90} INFO - Running: ['airflow', 'tasks', 'run', 'bharat_dag', 'task_1', 'scheduled__2024-05-03T05:52:00+00:00', '--job-id', '239', '--raw', '--subdir', 'DAGS_FOLDER/bharat2_dag.py', '--cfg-path', '/tmp/tmplln9uxed']
[2024-05-03T11:24:02.202+0530] {standard_task_runner.py:91} INFO - Job 239: Subtask task_1
[2024-05-03T11:24:02.216+0530] {task_command.py:426} INFO - Running <TaskInstance: bharat_dag.task_1 scheduled__2024-05-03T05:52:00+00:00 [running]> on host ninebit5lm
[2024-05-03T11:24:02.246+0530] {taskinstance.py:2644} INFO - Exporting env vars: AIRFLOW_CTX_DAG_OWNER='airflow' AIRFLOW_CTX_DAG_ID='bharat_dag' AIRFLOW_CTX_TASK_ID='task_1' AIRFLOW_CTX_EXECUTION_DATE='2024-05-03T05:52:00+00:00' AIRFLOW_CTX_TRY_NUMBER='1' AIRFLOW_CTX_DAG_RUN_ID='scheduled__2024-05-03T05:52:00+00:00'
[2024-05-03T11:24:02.247+0530] {taskinstance.py:430} INFO - ::endgroup::
[2024-05-03T11:24:02.247+0530] {taskinstance.py:441} INFO - ::group::Post task execution logs
[2024-05-03T11:24:02.247+0530] {taskinstance.py:2890} ERROR - Task failed with exception
Traceback (most recent call last):
  File "/usr/local/lib/python3.10/dist-packages/airflow/models/taskinstance.py", line 465, in _execute_task
    result = _execute_callable(context=context, **execute_callable_kwargs)
  File "/usr/local/lib/python3.10/dist-packages/airflow/models/taskinstance.py", line 432, in _execute_callable
    return execute_callable(context=context, **execute_callable_kwargs)
  File "/usr/local/lib/python3.10/dist-packages/airflow/models/baseoperator.py", line 400, in wrapper
    return func(self, *args, **kwargs)
  File "/usr/local/lib/python3.10/dist-packages/airflow/operators/python.py", line 235, in execute
    return_value = self.execute_callable()
  File "/usr/local/lib/python3.10/dist-packages/airflow/operators/python.py", line 252, in execute_callable
    return self.python_callable(*self.op_args, **self.op_kwargs)
  File "/home/bharat/airflow/dags/bharat2_dag.py", line 8, in task1
    print("the task1 number is" + random.randint(1, 100))
TypeError: can only concatenate str (not "int") to str
[2024-05-03T11:24:02.249+0530] {taskinstance.py:1205} INFO - Marking task as UP_FOR_RETRY. dag_id=bharat_dag, task_id=task_1, execution_date=20240503T055200, start_date=20240503T055402, end_date=20240503T055402
[2024-05-03T11:24:02.255+0530] {standard_task_runner.py:110} ERROR - Failed to execute job 239 for task task_1 (can only concatenate str (not "int") to str; 9796)
[2024-05-03T11:24:02.293+0530] {local_task_job_runner.py:240} INFO - Task exited with return code 1
[2024-05-03T11:24:02.304+0530] {taskinstance.py:3482} INFO - 0 downstream tasks scheduled from follow-on schedule check
[2024-05-03T11:24:02.304+0530] {local_task_job_runner.py:222} INFO - ::endgroup::
